[2022-03-06 04:52:18,194] {taskinstance.py:1032} INFO - Dependencies all met for <TaskInstance: upload_to_gcs_dag.kaggle_download scheduled__2022-03-05T00:00:00+00:00 [queued]>
[2022-03-06 04:52:18,227] {taskinstance.py:1032} INFO - Dependencies all met for <TaskInstance: upload_to_gcs_dag.kaggle_download scheduled__2022-03-05T00:00:00+00:00 [queued]>
[2022-03-06 04:52:18,228] {taskinstance.py:1238} INFO - 
--------------------------------------------------------------------------------
[2022-03-06 04:52:18,229] {taskinstance.py:1239} INFO - Starting attempt 1 of 2
[2022-03-06 04:52:18,231] {taskinstance.py:1240} INFO - 
--------------------------------------------------------------------------------
[2022-03-06 04:52:18,408] {taskinstance.py:1259} INFO - Executing <Task(BashOperator): kaggle_download> on 2022-03-05 00:00:00+00:00
[2022-03-06 04:52:18,420] {standard_task_runner.py:52} INFO - Started process 646 to run task
[2022-03-06 04:52:18,425] {standard_task_runner.py:76} INFO - Running: ['***', 'tasks', 'run', 'upload_to_gcs_dag', 'kaggle_download', 'scheduled__2022-03-05T00:00:00+00:00', '--job-id', '625', '--raw', '--subdir', 'DAGS_FOLDER/upload_to_gcs_dag.py', '--cfg-path', '/tmp/tmpf9uhohvu', '--error-file', '/tmp/tmp87kw91es']
[2022-03-06 04:52:18,426] {standard_task_runner.py:77} INFO - Job 625: Subtask kaggle_download
[2022-03-06 04:52:18,660] {logging_mixin.py:109} INFO - Running <TaskInstance: upload_to_gcs_dag.kaggle_download scheduled__2022-03-05T00:00:00+00:00 [running]> on host 5f012362ddb6
[2022-03-06 04:52:18,972] {taskinstance.py:1426} INFO - Exporting the following env vars:
AIRFLOW_CTX_DAG_OWNER=***
AIRFLOW_CTX_DAG_ID=upload_to_gcs_dag
AIRFLOW_CTX_TASK_ID=kaggle_download
AIRFLOW_CTX_EXECUTION_DATE=2022-03-05T00:00:00+00:00
AIRFLOW_CTX_DAG_RUN_ID=scheduled__2022-03-05T00:00:00+00:00
[2022-03-06 04:52:18,977] {subprocess.py:62} INFO - Tmp dir root location: 
 /tmp
[2022-03-06 04:52:18,981] {subprocess.py:74} INFO - Running command: ['bash', '-c', 'echo \'{"username":"jackhoover","key":"2511dc03985b0d90db3e847bfa8cfd18"}\' > kaggle.json && \\mkdir ~/.kaggle && \\mv kaggle.json ~/.kaggle && \\chmod 600 ~/.kaggle/kaggle.json && \\kaggle datasets download -d netflix-inc/netflix-prize-data']
[2022-03-06 04:52:19,009] {subprocess.py:85} INFO - Output:
[2022-03-06 04:52:19,427] {subprocess.py:89} INFO - bash: kaggle: command not found
[2022-03-06 04:52:19,428] {subprocess.py:93} INFO - Command exited with return code 127
[2022-03-06 04:52:19,676] {taskinstance.py:1700} ERROR - Task failed with exception
Traceback (most recent call last):
  File "/home/airflow/.local/lib/python3.7/site-packages/airflow/models/taskinstance.py", line 1329, in _run_raw_task
    self._execute_task_with_callbacks(context)
  File "/home/airflow/.local/lib/python3.7/site-packages/airflow/models/taskinstance.py", line 1455, in _execute_task_with_callbacks
    result = self._execute_task(context, self.task)
  File "/home/airflow/.local/lib/python3.7/site-packages/airflow/models/taskinstance.py", line 1511, in _execute_task
    result = execute_callable(context=context)
  File "/home/airflow/.local/lib/python3.7/site-packages/airflow/operators/bash.py", line 188, in execute
    f'Bash command failed. The command returned a non-zero exit code {result.exit_code}.'
airflow.exceptions.AirflowException: Bash command failed. The command returned a non-zero exit code 127.
[2022-03-06 04:52:19,689] {taskinstance.py:1277} INFO - Marking task as UP_FOR_RETRY. dag_id=upload_to_gcs_dag, task_id=kaggle_download, execution_date=20220305T000000, start_date=20220306T045218, end_date=20220306T045219
[2022-03-06 04:52:19,876] {standard_task_runner.py:92} ERROR - Failed to execute job 625 for task kaggle_download
Traceback (most recent call last):
  File "/home/airflow/.local/lib/python3.7/site-packages/airflow/task/task_runner/standard_task_runner.py", line 85, in _start_by_fork
    args.func(args, dag=self.dag)
  File "/home/airflow/.local/lib/python3.7/site-packages/airflow/cli/cli_parser.py", line 48, in command
    return func(*args, **kwargs)
  File "/home/airflow/.local/lib/python3.7/site-packages/airflow/utils/cli.py", line 92, in wrapper
    return f(*args, **kwargs)
  File "/home/airflow/.local/lib/python3.7/site-packages/airflow/cli/commands/task_command.py", line 298, in task_run
    _run_task_by_selected_method(args, dag, ti)
  File "/home/airflow/.local/lib/python3.7/site-packages/airflow/cli/commands/task_command.py", line 107, in _run_task_by_selected_method
    _run_raw_task(args, ti)
  File "/home/airflow/.local/lib/python3.7/site-packages/airflow/cli/commands/task_command.py", line 184, in _run_raw_task
    error_file=args.error_file,
  File "/home/airflow/.local/lib/python3.7/site-packages/airflow/utils/session.py", line 70, in wrapper
    return func(*args, session=session, **kwargs)
  File "/home/airflow/.local/lib/python3.7/site-packages/airflow/models/taskinstance.py", line 1329, in _run_raw_task
    self._execute_task_with_callbacks(context)
  File "/home/airflow/.local/lib/python3.7/site-packages/airflow/models/taskinstance.py", line 1455, in _execute_task_with_callbacks
    result = self._execute_task(context, self.task)
  File "/home/airflow/.local/lib/python3.7/site-packages/airflow/models/taskinstance.py", line 1511, in _execute_task
    result = execute_callable(context=context)
  File "/home/airflow/.local/lib/python3.7/site-packages/airflow/operators/bash.py", line 188, in execute
    f'Bash command failed. The command returned a non-zero exit code {result.exit_code}.'
airflow.exceptions.AirflowException: Bash command failed. The command returned a non-zero exit code 127.
[2022-03-06 04:52:19,900] {local_task_job.py:154} INFO - Task exited with return code 1
[2022-03-06 04:52:20,050] {local_task_job.py:264} INFO - 0 downstream tasks scheduled from follow-on schedule check
