[2022-03-06 04:52:18,006] {taskinstance.py:1032} INFO - Dependencies all met for <TaskInstance: upload_to_gcs_dag.to_csv scheduled__2022-03-05T00:00:00+00:00 [queued]>
[2022-03-06 04:52:18,022] {taskinstance.py:1032} INFO - Dependencies all met for <TaskInstance: upload_to_gcs_dag.to_csv scheduled__2022-03-05T00:00:00+00:00 [queued]>
[2022-03-06 04:52:18,022] {taskinstance.py:1238} INFO - 
--------------------------------------------------------------------------------
[2022-03-06 04:52:18,023] {taskinstance.py:1239} INFO - Starting attempt 1 of 2
[2022-03-06 04:52:18,023] {taskinstance.py:1240} INFO - 
--------------------------------------------------------------------------------
[2022-03-06 04:52:18,195] {taskinstance.py:1259} INFO - Executing <Task(PythonOperator): to_csv> on 2022-03-05 00:00:00+00:00
[2022-03-06 04:52:18,205] {standard_task_runner.py:52} INFO - Started process 645 to run task
[2022-03-06 04:52:18,218] {standard_task_runner.py:76} INFO - Running: ['***', 'tasks', 'run', 'upload_to_gcs_dag', 'to_csv', 'scheduled__2022-03-05T00:00:00+00:00', '--job-id', '624', '--raw', '--subdir', 'DAGS_FOLDER/upload_to_gcs_dag.py', '--cfg-path', '/tmp/tmphmw4eg92', '--error-file', '/tmp/tmpr9ulbly8']
[2022-03-06 04:52:18,230] {standard_task_runner.py:77} INFO - Job 624: Subtask to_csv
[2022-03-06 04:52:18,345] {logging_mixin.py:109} INFO - Running <TaskInstance: upload_to_gcs_dag.to_csv scheduled__2022-03-05T00:00:00+00:00 [running]> on host 5f012362ddb6
[2022-03-06 04:52:18,971] {taskinstance.py:1426} INFO - Exporting the following env vars:
AIRFLOW_CTX_DAG_OWNER=***
AIRFLOW_CTX_DAG_ID=upload_to_gcs_dag
AIRFLOW_CTX_TASK_ID=to_csv
AIRFLOW_CTX_EXECUTION_DATE=2022-03-05T00:00:00+00:00
AIRFLOW_CTX_DAG_RUN_ID=scheduled__2022-03-05T00:00:00+00:00
[2022-03-06 04:52:18,979] {taskinstance.py:1700} ERROR - Task failed with exception
Traceback (most recent call last):
  File "/home/airflow/.local/lib/python3.7/site-packages/airflow/models/taskinstance.py", line 1329, in _run_raw_task
    self._execute_task_with_callbacks(context)
  File "/home/airflow/.local/lib/python3.7/site-packages/airflow/models/taskinstance.py", line 1455, in _execute_task_with_callbacks
    result = self._execute_task(context, self.task)
  File "/home/airflow/.local/lib/python3.7/site-packages/airflow/models/taskinstance.py", line 1511, in _execute_task
    result = execute_callable(context=context)
  File "/home/airflow/.local/lib/python3.7/site-packages/airflow/operators/python.py", line 174, in execute
    return_value = self.execute_callable()
  File "/home/airflow/.local/lib/python3.7/site-packages/airflow/operators/python.py", line 185, in execute_callable
    return self.python_callable(*self.op_args, **self.op_kwargs)
  File "/opt/airflow/dags/upload_to_gcs_dag.py", line 28, in convert_to_csv
    with open(file) as f:
FileNotFoundError: [Errno 2] No such file or directory: 'combined_data_1.txt'
[2022-03-06 04:52:19,016] {taskinstance.py:1277} INFO - Marking task as UP_FOR_RETRY. dag_id=upload_to_gcs_dag, task_id=to_csv, execution_date=20220305T000000, start_date=20220306T045218, end_date=20220306T045219
[2022-03-06 04:52:19,367] {standard_task_runner.py:92} ERROR - Failed to execute job 624 for task to_csv
Traceback (most recent call last):
  File "/home/airflow/.local/lib/python3.7/site-packages/airflow/task/task_runner/standard_task_runner.py", line 85, in _start_by_fork
    args.func(args, dag=self.dag)
  File "/home/airflow/.local/lib/python3.7/site-packages/airflow/cli/cli_parser.py", line 48, in command
    return func(*args, **kwargs)
  File "/home/airflow/.local/lib/python3.7/site-packages/airflow/utils/cli.py", line 92, in wrapper
    return f(*args, **kwargs)
  File "/home/airflow/.local/lib/python3.7/site-packages/airflow/cli/commands/task_command.py", line 298, in task_run
    _run_task_by_selected_method(args, dag, ti)
  File "/home/airflow/.local/lib/python3.7/site-packages/airflow/cli/commands/task_command.py", line 107, in _run_task_by_selected_method
    _run_raw_task(args, ti)
  File "/home/airflow/.local/lib/python3.7/site-packages/airflow/cli/commands/task_command.py", line 184, in _run_raw_task
    error_file=args.error_file,
  File "/home/airflow/.local/lib/python3.7/site-packages/airflow/utils/session.py", line 70, in wrapper
    return func(*args, session=session, **kwargs)
  File "/home/airflow/.local/lib/python3.7/site-packages/airflow/models/taskinstance.py", line 1329, in _run_raw_task
    self._execute_task_with_callbacks(context)
  File "/home/airflow/.local/lib/python3.7/site-packages/airflow/models/taskinstance.py", line 1455, in _execute_task_with_callbacks
    result = self._execute_task(context, self.task)
  File "/home/airflow/.local/lib/python3.7/site-packages/airflow/models/taskinstance.py", line 1511, in _execute_task
    result = execute_callable(context=context)
  File "/home/airflow/.local/lib/python3.7/site-packages/airflow/operators/python.py", line 174, in execute
    return_value = self.execute_callable()
  File "/home/airflow/.local/lib/python3.7/site-packages/airflow/operators/python.py", line 185, in execute_callable
    return self.python_callable(*self.op_args, **self.op_kwargs)
  File "/opt/airflow/dags/upload_to_gcs_dag.py", line 28, in convert_to_csv
    with open(file) as f:
FileNotFoundError: [Errno 2] No such file or directory: 'combined_data_1.txt'
[2022-03-06 04:52:19,396] {local_task_job.py:154} INFO - Task exited with return code 1
[2022-03-06 04:52:19,549] {local_task_job.py:264} INFO - 0 downstream tasks scheduled from follow-on schedule check
